Environment:


Request Method: POST
Request URL: http://recipes.missguegan.com/mealplanner/recipe/save/None/

Django Version: 1.9.4
Python Version: 3.5.1
Installed Applications:
['mealplanner.apps.MealplannerConfig',
 'django.contrib.admin',
 'django.contrib.auth',
 'django.contrib.contenttypes',
 'django.contrib.sessions',
 'django.contrib.messages',
 'django.contrib.staticfiles']
Installed Middleware:
['django.middleware.security.SecurityMiddleware',
 'django.contrib.sessions.middleware.SessionMiddleware',
 'django.middleware.common.CommonMiddleware',
 'django.middleware.csrf.CsrfViewMiddleware',
 'django.contrib.auth.middleware.AuthenticationMiddleware',
 'django.contrib.auth.middleware.SessionAuthenticationMiddleware',
 'django.contrib.messages.middleware.MessageMiddleware',
 'django.middleware.clickjacking.XFrameOptionsMiddleware']



Traceback:

File "/home/jbutterf/webapps/recipes/lib/python3.5/Django-1.9.4-py3.5.egg/django/core/handlers/base.py" in get_response
  149.                     response = self.process_exception_by_middleware(e, request)

File "/home/jbutterf/webapps/recipes/lib/python3.5/Django-1.9.4-py3.5.egg/django/core/handlers/base.py" in get_response
  147.                     response = wrapped_callback(request, *callback_args, **callback_kwargs)

File "/home/jbutterf/webapps/recipes/lib/python3.5/Django-1.9.4-py3.5.egg/django/contrib/auth/decorators.py" in _wrapped_view
  23.                 return view_func(request, *args, **kwargs)

File "/home/jbutterf/webapps/recipes/recipes/mealplanner/views.py" in saveRecipe
  100.             saveRecipeFromForm(request, form, recipe)

File "/home/jbutterf/webapps/recipes/recipes/mealplanner/views.py" in saveRecipeFromForm
  118.         [ingredient,_] = Ingredient.objects.get_or_create(user=request.user,name=name)

File "/home/jbutterf/webapps/recipes/lib/python3.5/Django-1.9.4-py3.5.egg/django/db/models/manager.py" in manager_method
  122.                 return getattr(self.get_queryset(), name)(*args, **kwargs)

File "/home/jbutterf/webapps/recipes/lib/python3.5/Django-1.9.4-py3.5.egg/django/db/models/query.py" in get_or_create
  465.             return self.get(**lookup), False

File "/home/jbutterf/webapps/recipes/lib/python3.5/Django-1.9.4-py3.5.egg/django/db/models/query.py" in get
  391.             (self.model._meta.object_name, num)

Exception Type: MultipleObjectsReturned at /mealplanner/recipe/save/None/
Exception Value: get() returned more than one Ingredient -- it returned 2!
